Workbook

Sheet Start tutaj
B2: MapJob - Warszawa B2B Cold-Calling CRM
B3: Gotowy CRM do telefonowania - nauczysz sie obslugi w 10 min, wypelnisz w 60 min.
B5: Jak uzywac tego pliku (5 krokow, 60 minut)
B6: 1. Wybierz segment (5 min)
B7: Przejdz do arkusza [Segmenty] - zobaczysz 4 segmenty z priorytetem. W pierwszym tygodniu dzwonisz TYLKO do jednego. Rekomendacja: Zarzadcy nieruchomosci (5 gwiazdek priorytetu).
B8: 2. Otworz gotowe zapytania Google Maps (20 min)
B9: Arkusz [Google Maps Warszawa] ma 72 klikalne linki (18 dzielnic x 4 segmenty). Klikasz - Google Maps otwiera wyszukiwanie - kopiujesz dane firmy do arkusza [Lista firm].
B10: 3. Wpisz firmy do arkusza [Lista firm] (30 min)
B11: Kolumny maja dropdowny (Segment, Priorytet, Status, Zrodlo, Dzielnica). Nie musisz pamietac opcji - klikasz w komorke, wybierasz z listy. Cel: 50+ firm.
B12: 4. Oznacz priorytet zielony / zolty / czerwony (5 min)
B13: ZIELONY TOP = >20 opinii Google + >4.0 gwiazdki + dzialajaca strona. ZOLTY Sredni = 5-20 opinii LUB 3.5-4.0 gwiazdki. CZERWONY Niski = <5 opinii lub brak strony (pomijasz na start).
B14: 5. Sprawdz [Pre-flight] i zacznij dzwonic
... B24: - Miesiac 3: 60-75 firm = masz sprawdzony skrypt = czas na skalowanie

Sheet Lista firm
A1: Lp | B1: Data dodania | C1: Nazwa firmy | D1: Segment | E1: Priorytet | F1: Dzielnica | G1: Telefon | H1: Email | I1: Strona www | J1: Adres | K1: Osoba kontaktowa | L1: Stanowisko | M1: Opinie Google (liczba) | N1: Gwiazdki Google | O1: Zrodlo | P1: Status | Q1: Data ostatniego kontaktu | R1: Data follow-up | S1: Notatki z researchu (90 sek) | T1: Notatki z rozmowy
A2: =IF(C2="","",ROW()-1) | B2: 46135 | C2: Zaklad Gospodarowania Nieruchomosciami w Dzielnicy Mokotow m.st. Warszawy | D2: Zarzadcy nieruchomosci | E2: TOP (zielony) | F2: Mokotow | G2: +48 22 549 37 00 | J2: Irysowa 19 | L2: Zarzadca / Inspektor nadzoru / Konserwator | M2: 115 | N2: 4 | O2: Google Maps | P2: Nowa | S2: Urzad dzielnicowy - zarzadza nier. komunalnymi Mokotowa. Ogromny klient potencjalny. 4.0 gwiazdki - 115 opinii.
A3: =IF(C3="","",ROW()-1) | B3: 46135 | C3: Emco | Zarzadzanie Nieruchomosciami | D3: Zarzadcy nieruchomosci | E3: TOP (zielony) | F3: Mokotow | G3: +48 22 406 52 45 | J3: Bialy Kamien 5/U3 | L3: Zarzadca / Inspektor nadzoru / Konserwator | M3: 220 | N3: 4.5 | O3: Google Maps | P3: Nowa | S3: Duza prywatna firma ZN, 220 opinii i 4.5 gw. - top segment. Wysoka szansa zgody.
A4: =IF(C4="","",ROW()-1) | B4: 46135 | C4: Polkowska. Administracja Domow Mieszkalnych | D4: Zarzadcy nieruchomosci | E4: Sredni (zolty) | F4: Mokotow | G4: (zweryfikuj na Maps) | J4: Polkowska 7 | L4: Zarzadca / Inspektor nadzoru / Konserwator | M4: 19 | N4: 4.6 | O4: Google Maps | P4: Nowa | S4: UWAGA: numer w Maps byl niepelny - otworz link Maps i sprawdz. Dobre opinie (4.6).
A5: =IF(C5="","",ROW()-1) | B5: 46135 | C5: Concordia ZN - Zarzadzanie Nieruchomosciami Warszawa | D5: Zarzadcy nieruchomosci | E5: TOP (zielony) | F5: Mokotow | G5: +48 501 504 961 | J5: sw. Bonifacego 100 | L5: Zarzadca / Inspektor nadzoru / Konserwator | M5: 49 | N5: 4.1 | O5: Google Maps | P5: Nowa | S5: Dobra srednia firma. Ma strone. 4.1 z 49 opinii.
A6: =IF(C6="","",ROW()-1) | B6: 46135 | C6: INTER-EJ Zarzadzanie i administrowanie nieruchomosciami | D6: Zarzadcy nieruchomosci | E6: Niski (czerwony) | F6: Mokotow | G6: +48 22 853 47 33 | J6: Zygmunta Modzelewskiego 27 | L6: Zarzadca / Inspektor nadzoru / Konserwator | M6: 45 | N6: 2.3 | O6: Google Maps | P6: Nowa | S6: NISKI priorytet - 2.3 gw. z 45 opinii. Pomin na start, duzo narzekan klientow = trudny rozmowca.
A7: =IF(C7="","",ROW()-1) | B7: 46135 | C7: Patron. Firma zarzadzajaca nieruchomosciami - Lubomirski J. | D7: Zarzadcy nieruchomosci | E7: Niski (czerwony) | F7: Mokotow | G7: +48 22 844 26 91 | J7: Aleksandra Wejnerta 12 | L7: Zarzadca / Inspektor nadzoru / Konserwator | M7: 36 | N7: 3.3 | O7: Google Maps | P7: Nowa | S7: 3.3 gw. - slaba jakosc, firma rodzinna Lubomirski. Last resort.
A8: =IF(C8="","",ROW()-1) | B8: 46135 | C8: Polska Grupa Najmu - Zarzadzanie mieszkaniami | D8: Zarzadcy nieruchomosci | E8: Sredni (zolty) | F8: Mokotow | G8: +48 602 526 221 | J8: Bobrowiecka 1A | L8: Zarzadca / Inspektor nadzoru / Konserwator | M8: 7 | N8: 5 | O8: Google Maps | P8: Nowa | S8: Mala firma, skupiona na najmie (nie typowe ZN). 5.0/7 opinii.
A9: =IF(C9="","",ROW()-1) | B9: 46135 | C9: Mieszkaj Zarzadzanie Najmem Warszawa | D9: Zarzadcy nieruchomosci | E9: Sredni (zolty) | F9: Mokotow | G9: +48 796 163 823 | J9: Pulawska 77/U5 | L9: Zarzadca / Inspektor nadzoru / Konserwator | M9: 5 | N9: 5 | O9: Google Maps | P9: Nowa | S9: Mala firma (Jurek Wichowski), skupiona na najmie.
A10: =IF(C10="","",ROW()-1) | B10: 46135 | C10: FILARIO - Zarzadzanie i Administrowanie Nieruchomosciami | D10: Zarzadcy nieruchomosci | E10: TOP (zielony) | F10: Wola | G10: +48 539 365 272 | J10: Grzybowska 87 | L10: Zarzadca / Inspektor nadzoru / Konserwator | M10: 41 | N10: 4.9 | O10: Google Maps | P10: Nowa | S10: Top priorytet - 4.9 gw. z 41 opinii. Rozumieja wspolnoty mieszkaniowe.
A11: =IF(C11="","",ROW()-1) | B11: 46135 | C11: Zaklad Gospodarowania Nieruchomosciami Wola (Nowolipki) | D11: Zarzadcy nieruchomosci | E11: Niski (czerwony) | F11: Wola | G11: +48 22 838 49 75 | J11: Nowolipki 16 | L11: Zarzadca / Inspektor nadzoru / Konserwator | M11: 78 | N11: 3.2 | O11: Google Maps | P11: Nowa | S11: Urzad dzielnicy Wola. 3.2 gw. - dlaczego niski? Moze ciekawy ale trudny.
A12: =IF(C12="","",ROW()-1) | B12: 46135 | C12: ZGN Wola (Bema 70) | D12: Zarzadcy nieruchomosci | E12: Niski (czerwony) | F12: Wola | G12: +48 22 495 81 00 | J12: Jozefa Bema 70 | L12: Zarzadca / Inspektor nadzoru / Konserwator | M12: 36 | N12: 3.2 | O12: Google Maps | P12: Nowa | S12: Inny oddzial ZGN Wola. Urzad administracji lokalnej. 3.2 gw.
A13: =IF(C13="","",ROW()-1) | B13: 46135 | C13: P.Z. Partner Sp. z o.o. | D13: Zarzadcy nieruchomosci | E13: Sredni (zolty) | F13: Wola | G13: +48 696 421 594 | J13: Wolska 84/U115 | L13: Zarzadca / Inspektor nadzoru / Konserwator | M13: 14 | N13: 5 | O13: Google Maps | P13: Nowa | S13: Mala firma, 5.0 gw. z 14 opinii. Profesjonalni wg opinii - dobry lead.
... A23: =IF(C23="","",ROW()-1) | B23: 46135 | C23: Euro-House - Agencja Nieruchomosci Komercyjnych | D23: Agencje nieruchomosci | E23: TOP (zielony) | F23: Ursynow | G23: +48 504 898 106 | J23: Braci Wagow 20/U1 | L23: Agent / Manager biura | M23: 141 | N23: 4.9 | O23: Google Maps | P23: Nowa | S23: Agencja komercyjna. 141 opinii 4.9. Pan Pawlaczyk polecany. Biuro segmentu TOP.
A24: =IF(C24="","",ROW()-1) | B24: 46135 | C24: Zarzadzanie Najmem GRAPAW - Grazyna Pawlak | D24: Agencje nieruchomosci | E24: Niski (czerwony) | F24: Ursynow | G24: +48 531 188 303 | J24: Kabacki Dukt 6/40 | L24: Agent / Manager biura | O24: Google Maps | P24: Nowa | S24: Brak opinii. Niski priorytet - nie wiadomo czy firma aktywna.
A25: =IF(C25="","",ROW()-1) | B25: 46135 | C25: AD.DRAGOWSKI - Warszawska agencja nieruchomosci od 1986 | D25: Agencje nieruchomosci | E25: TOP (zielony) | F25: Ursynow | G25: +48 22 827 90 83 | J25: Al. KEN 90 | L25: Agent / Manager biura | M25: 21 | N25: 4.4 | O25: Google Maps | P25: Nowa | S25: Agencja nier. od 1986 r. Solidna. 4.4 gw 21 opinii.
A26: =IF(C26="","",ROW()-1) | B26: 46135 | C26: Sweden House - Zarzadzanie najmem Warszawa | D26: Zarzadcy nieruchomosci | E26: TOP (zielony) | F26: Srodmiescie | G26: +48 22 290 39 02 | J26: Al. Jana Pawla II 64/D | L26: Zarzadca / Inspektor nadzoru / Konserwator | M26: 98 | N26: 4.8 | O26: Google Maps | P26: Nowa | S26: 98 opinii 4.8 - top firma w Srodmiesciu. Profesjonalizm chwalony. Lead grade A.
A27: =IF(C27="","",ROW()-1) | B27: 46135 | C27: Jakub Bezdomny - Nieruchomosci w Warszawie | D27: Agencje nieruchomosci | E27: Sredni (zolty) | F27: Srodmiescie | G27: +48 22 250 12 22 | J27: Nowy Swiat 42 | L27: Agent / Manager biura | M27: 17 | N27: 5 | O27: Google Maps | P27: Nowa | S27: Agencja + ZN. 5.0 z 17 opinii. Jakub Bezdomny - osobowa marka.
A28: =IF(C28="","",ROW()-1) | B28: 46135 | C28: Zaklad Gospodarowania Nieruchomosciami Srodmiescie | D28: Zarzadcy nieruchomosci | E28: TOP (zielony) | F28: Srodmiescie | G28: +48 22 336 61 20 | J28: Szwolezerow 5 | L28: Zarzadca / Inspektor nadzoru / Konserwator | M28: 40 | N28: 4.1 | O28: Google Maps | P28: Nowa | S28: ZGN Srodmiescie - duzy klient potencjalny. 4.1 gw 40 opinii. Komunalne.
A29: =IF(C29="","",ROW()-1) | B29: 46135 | C29: WESTATE SRODMIESCIE | D29: Agencje nieruchomosci | E29: TOP (zielony) | F29: Srodmiescie | G29: +48 22 428 26 81 | J29: Niecala 7 | L29: Agent / Manager biura | M29: 138 | N29: 4.9 | O29: Google Maps | P29: Nowa | S29: Agencja nier. 138 opinii 4.9 - top. Agencja wiec mniej ZN-segmentu.
A30: =IF(C30="","",ROW()-1) | B30: 46135 | C30: Prodoma - zarzadzanie najmem | D30: Zarzadcy nieruchomosci | E30: TOP (zielony) | F30: Srodmiescie | G30: +48 22 299 20 70 | J30: Chmielna 2/II | L30: Zarzadca / Inspektor nadzoru / Konserwator | M30: 92 | N30: 4.5 | O30: Google Maps | P30: Nowa | S30: 92 opinii 4.5 - solidny lead. Dobra wiadomosc: skaluja duze portfele.
A31: =IF(C31="","",ROW()-1) | B31: 46135 | C31: Jakub Bezdomny - Posrednictwo i Zarzadzanie | D31: Agencje nieruchomosci | E31: TOP (zielony) | F31: Srodmiescie | G31: +48 22 250 12 22 | J31: Tytusa Chalubinskiego 8 | L31: Agent / Manager biura | M31: 26 | N31: 4.5 | O31: Google Maps | P31: Nowa | S31: Drugi oddzial Jakuba. Nie dublowac telefonu - jedna rozmowa.
A32: =IF(C32="","",ROW()-1) | B32: 46135 | C32: PYRAMID Centrum Zarzadzania Nieruchomosciami | D32: Zarzadcy nieruchomosci | E32: Niski (czerwony) | F32: Srodmiescie | G32: +48 22 622 07 67 | J32: Zurawia 32/pokoj 56 | L32: Zarzadca / Inspektor nadzoru / Konserwator | M32: 10 | N32: 2.9 | O32: Google Maps | P32: Nowa | S32: 2.9 gw - niski priorytet. Pomin na start.
A33: =IF(C33="","",ROW()-1) | B33: 46135 | C33: SDP Nieruchomosci | D33: Agencje nieruchomosci | E33: TOP (zielony) | F33: Srodmiescie | G33: +48 602 101 602 | J33: Wilcza 66/68 | L33: Agent / Manager biura | M33: 157 | N33: 4.9 | O33: Google Maps | P33: Nowa | S33: Agencja nieruchomosci TOP - 157 op 4.9. Pani Wiecek polecana.
A34: =IF(C34="","",ROW()-1) | B34: 46135 | C34: Lemmonhouse - zarzadzanie nieruchomosciami | D34: Zarzadcy nieruchomosci | E34: Niski (czerwony) | F34: Wilanow | G34: +48 22 885 30 20 | J34: Sarmacka 18/L143 | L34: Zarzadca / Inspektor nadzoru / Konserwator | M34: 52 | N34: 3.2 | O34: Google Maps | P34: Nowa | S34: 3.2 gw - narzekania na czas naprawy. Niski priorytet.
A35: =IF(C35="","",ROW()-1) | B35: 46135 | C35: Lux Dom Sp. z o.o. | D35: Zarzadcy nieruchomosci | E35: Niski (czerwony) | F35: Wilanow | G35: +48 512 031 805 | J35: Al. Wilanowska 9 | L35: Zarzadca / Inspektor nadzoru / Konserwator | M35: 166 | N35: 2.3 | O35: Google Maps | P35: Nowa | S35: 2.3 gw - pomin. Mieszkancy skarza sie. Lead grade D.
A36: =IF(C36="","",ROW()-1) | B36: 46135 | C36: Wspolnota Mieszkaniowa Ostoja Wilanow | D36: Zarzadcy nieruchomosci | E36: TOP (zielony) | F36: Wilanow | G36: +48 797 027 888 | J36: Ostoja Wilanow - Prymasa Hlonda | L36: Zarzadca / Inspektor nadzoru / Konserwator | M36: 462 | N36: 4.2 | O36: Google Maps | P36: Nowa | S36: OGROMNA wspolnota (462 opinii!). Najlepsze osiedle w Wilanowie. Priorytet top - wolumen zlecen ogromny.
... A79: =IF(C79="","",ROW()-1) | B79: 46135 | C79: Kodif - Elektryk | D79: Firmy budowlane | E79: TOP (zielony) | F79: Bemowo | G79: +48 792 311 822 | J79: Blatona 4/41 | L79: Wlasciciel / Elektryk | M79: 46 | N79: 5 | O79: Google Maps | P79: Nowa | S79: [FACHOWIEC - nie klient] 5.0 gw 46 opinii. Teleporada - innowacyjny. Top lead.
A80: =IF(C80="","",ROW()-1) | B80: 46135 | C80: Uslugi elektryczne - Instalacje elektryczne | D80: Firmy budowlane | E80: TOP (zielony) | G80: +48 503 139 799 | L80: Wlasciciel / Elektryk | M80: 22 | N80: 4.5 | O80: Google Maps | P80: Nowa | S80: [FACHOWIEC - nie klient] 4.5 gw 22 opinii. Brak adresu w Maps - zweryfikuj geo przy rozmowie.
A81: =IF(C81="","",ROW()-1) | B81: 46135 | C81: Opal Wojciech Poplawski | D81: Firmy budowlane | E81: TOP (zielony) | G81: +48 885 765 192 | L81: Wlasciciel / Elektryk | M81: 155 | N81: 4.7 | O81: Google Maps | P81: Nowa | S81: [FACHOWIEC - nie klient] 155 opinii 4.7 gw. Kompetentny, kontaktowy. Top lead mimo braku adresu.
A82: =IF(C82="","",ROW()-1) | B82: 46135 | C82: pomiary.mobi Elektryk - Pogotowie Elektryczne | D82: Firmy budowlane | E82: TOP (zielony) | F82: Wola | G82: +48 798 148 838 | J82: 1 Sierpnia 40A | L82: Wlasciciel / Elektryk | M82: 144 | N82: 5 | O82: Google Maps | P82: Nowa | S82: [FACHOWIEC - nie klient] 5.0 gw 144 opinii. Profesjonalizm top. Lead grade A.
A83: =IF(C83="","",ROW()-1) | B83: 46135 | C83: Elektryk Warszawa Instalacje elektryczne | D83: Firmy budowlane | E83: TOP (zielony) | F83: Ursynow | G83: +48 600 608 874 | J83: Mrowcza 33A | L83: Wlasciciel / Elektryk | M83: 84 | N83: 5 | O83: Google Maps | P83: Nowa | S83: [FACHOWIEC - nie klient] 5.0 gw 84 opinii. Udokumentowane realizacje. Top lead.
A84: =IF(C84="","",ROW()-1) | B84: 46135 | C84: Elektryk Mokotow | D84: Firmy budowlane | E84: Sredni (zolty) | F84: Mokotow | G84: +48 666 257 492 | J84: Grupy AK Polnoc 13 | L84: Wlasciciel / Elektryk | M84: 8 | N84: 5 | O84: Google Maps | P84: Nowa | S84: [FACHOWIEC - nie klient] 5.0 gw 8 opinii. Profesjonalista. Sredni lead.
A85: =IF(C85="","",ROW()-1) | B85: 46135 | C85: Elektryk (Batorego) | D85: Firmy budowlane | E85: TOP (zielony) | F85: Mokotow | G85: +48 573 307 877 | J85: Stefana Batorego 18/108 | L85: Wlasciciel / Elektryk | M85: 25 | N85: 4.8 | O85: Google Maps | P85: Nowa | S85: [FACHOWIEC - nie klient] 4.8 gw 25 opinii. Czynne 24h. Solidny elektryk.
A86: =IF(C86="","",ROW()-1) | B86: 46135 | C86: Elektryk 24h Warszawa (Postepu) | D86: Firmy budowlane | E86: TOP (zielony) | F86: Mokotow | G86: +48 507 507 206 | J86: Postepu 18/B | L86: Wlasciciel / Elektryk | M86: 43 | N86: 5 | O86: Google Maps | P86: Nowa | S86: [FACHOWIEC - nie klient] 5.0 gw 43 opinii. Pan Adam - przemily fachowiec. Lead grade A.
A87: =IF(C87="","",ROW()-1) | B87: 46135 | C87: #bezpiecznainstalacjaelektryczna / ELEKTRODAN | D87: Firmy budowlane | E87: Sredni (zolty) | F87: Mokotow | G87: +48 502 277 855 | J87: Sniardwy 4/24 / Bialy Kamien 1 | L87: Wlasciciel / Elektryk | M87: 12 | N87: 5 | O87: Google Maps | P87: Nowa | S87: [FACHOWIEC - nie klient] Pan Daniel. 2 lokalizacje w Maps ten sam numer. 5.0 gw 12 opinii + 3.8/6 drugie. Top.
A88: =IF(C88="","",ROW()-1) | B88: 46135 | C88: Marek (elektryk Gandhiego) | D88: Firmy budowlane | E88: Sredni (zolty) | F88: Mokotow | G88: +48 515 455 455 | J88: Mahatmy Gandhiego 5 | L88: Wlasciciel / Elektryk | M88: 7 | N88: 5 | O88: Google Maps | P88: Nowa | S88: [FACHOWIEC - nie klient] 5.0 gw 7 opinii. Estetyka i terminowosc.
A89: =IF(C89="","",ROW()-1) | B89: 46135 | C89: Dobry Elektryk Warszawa | D89: Firmy budowlane | E89: Niski (czerwony) | F89: Mokotow | G89: +48 601 318 219 | J89: sw. Bonifacego 10 | L89: Wlasciciel / Elektryk | M89: 7 | N89: 3.9 | O89: Google Maps | P89: Nowa | S89: [FACHOWIEC - nie klient] 3.9 gw 7 opinii. Sredni lead - rozsadne ceny.
A90: =IF(C90="","",ROW()-1) | B90: 46135 | C90: Elektryk Ursynow/Mokotow/Wilanow - Naprawy | D90: Firmy budowlane | E90: Sredni (zolty) | F90: Mokotow | G90: +48 573 493 809 | J90: Magellana | L90: Wlasciciel / Elektryk | M90: 8 | N90: 5 | O90: Google Maps | P90: Nowa | S90: [FACHOWIEC - nie klient] Oblsuguje 3 dzielnice. 5.0 gw 8 opinii. Doswiadczony.
A91: =IF(C91="","",ROW()-1) | B91: 46135 | C91: Elektryk Wola Warszawa | D91: Firmy budowlane | E91: Sredni (zolty) | F91: Wola | G91: +48 881 758 758 | J91: Eustachego Tyszkiewicza 7/9/m47 | L91: Wlasciciel / Elektryk | M91: 17 | N91: 5 | O91: Google Maps | P91: Nowa | S91: [FACHOWIEC - nie klient] 5.0 gw 17 opinii. Swietny fachowiec z doswiadczeniem. Lead grade A.
...

Sheet Segmenty
B2: 4 segmenty B2B - ktorego dnia, do kogo, po co
B4: Segment | C4: Priorytet | D4: Dlaczego ten segment | E4: Kogo prosisz na linii
B5: Zarzadcy nieruchomosci | C5: 5 gwiazdek | D5: Ciagly bol (awarie w budynkach). Sami podejmuja decyzje. Malo technofobiczni (uzywaja juz ERP/CRM). Najwiekszy ROI z telefonu. | E5: Zarzadca ds. technicznych | Inspektor nadzoru | Konserwator | Prezes (male wspolnoty)
B6: Firmy budowlane / deweloperzy | C6: 4 gwiazdki | D6: Kara umowna za opoznienie = ogromny bol. Stale szukaja podwykonawcow. Ale gatekeeperzy twardsi - trzeba sie przebic przez sekretariat. | E6: Kierownik budowy | Specjalista ds. zaopatrzenia | Dyrektor operacyjny | Wlasciciel (firmy do 10 osob)
B7: Agencje nieruchomosci | C7: 3 gwiazdki | D7: Cykliczny bol (przed kazda sprzedaza cos trzeba naprawic). Nizsza pilnosc - poczekaja az cie sprawdza. Dobry segment na srodku tygodnia. | E7: Agent nieruchomosci (zwykle decyduje sam) | Manager biura | Dyrektor obslugi klienta
B8: HR / Duzi pracodawcy | C8: 3 gwiazdki | D8: Fabryki, hotele, logistyka. Szukaja fachowcow stale. Ale cykl decyzyjny dlugi - dzialasz na dluzsza mete. Wysoka wartosc pojedynczego leadu. | E8: Specjalista HR (rekrutacja techniczna) | Kierownik utrzymania ruchu | Dyrektor techniczny | Recruitment Business Partner
B11: Kiedy dzwonic (per segment)
B12: Dzien | C12: Godzina | D12: Segment | E12: Uwaga
B13: Poniedzialek | C13: 9:00 - 10:30 | D13: Zarzadcy nieruchomosci | E13: Po weekendzie maja swieza liste awarii
B14: Poniedzialek | C14: 14:00 - 16:00 | D14: Agencje nieruchomosci | E14: Klienci dzwonia rano - agent odbierze po obiedzie
B15: Wt / Sr / Czw | C15: 10:00 - 11:30 | D15: Firmy budowlane | E15: Kierownik budowy jest w biurze miedzy 10-12
B16: Wt / Sr / Czw | C16: 13:00 - 15:00 | D16: HR / Duzi pracodawcy | E16: Po obiedzie, przed koncem dnia rekrutera
B17: Piatek | C17: 13:00 - 15:00 | D17: Follow-upy + callbacki | E17: Nie nowe firmy w piatek po 15:00 (weekend w glowie)
B19: NIE dzwonimy: Pon 8:00-9:00 (odprawa) | Pt po 16:00 (weekend) | Wt 11:45 (glodni) | swieta +/- 1 dzien

Sheet Google Maps Warszawa
B2: 72 gotowe zapytania Google Maps - Warszawa (18 dzielnic x 4 segmenty)
B3: Kliknij w link - Google Maps otworzy wyszukiwanie - skopiuj firme do arkusza [Lista firm].
B5: Dzielnica | C5: Zarzadcy nieruchomosci | D5: Firmy budowlane | E5: Agencje nieruchomosci | F5: HR / Duzi pracodawcy
B6: Bemowo | C6: =HYPERLINK("https://www.google.com/maps/search/zarzadca+nieruchomosci+Bemowo+Warszawa","SZUKAJ: zarzadca nieruchomosci Bemowo Warszawa") | D6: =HYPERLINK("https://www.google.com/maps/search/firma+remontowa+Bemowo+Warszawa","SZUKAJ: firma remontowa Bemowo Warszawa") | E6: =HYPERLINK("https://www.google.com/maps/search/biuro+nieruchomosci+Bemowo+Warszawa","SZUKAJ: biuro nieruchomosci Bemowo Warszawa") | F6: =HYPERLINK("https://www.google.com/maps/search/fabryka+Bemowo+Warszawa","SZUKAJ: fabryka Bemowo Warszawa")
B7: Bialoleka | C7: =HYPERLINK("https://www.google.com/maps/search/zarzadca+nieruchomosci+Bialoleka+Warszawa","SZUKAJ: zarzadca nieruchomosci Bialoleka Warszawa") | D7: =HYPERLINK("https://www.google.com/maps/search/firma+remontowa+Bialoleka+Warszawa","SZUKAJ: firma remontowa Bialoleka Warszawa") | E7: =HYPERLINK("https://www.google.com/maps/search/biuro+nieruchomosci+Bialoleka+Warszawa","SZUKAJ: biuro nieruchomosci Bialoleka Warszawa") | F7: =HYPERLINK("https://www.google.com/maps/search/fabryka+Bialoleka+Warszawa","SZUKAJ: fabryka Bialoleka Warszawa")
B8: Bielany | C8: =HYPERLINK("https://www.google.com/maps/search/zarzadca+nieruchomosci+Bielany+Warszawa","SZUKAJ: zarzadca nieruchomosci Bielany Warszawa") | D8: =HYPERLINK("https://www.google.com/maps/search/firma+remontowa+Bielany+Warszawa","SZUKAJ: firma remontowa Bielany Warszawa") | E8: =HYPERLINK("https://www.google.com/maps/search/biuro+nieruchomosci+Bielany+Warszawa","SZUKAJ: biuro nieruchomosci Bielany Warszawa") | F8: =HYPERLINK("https://www.google.com/maps/search/fabryka+Bielany+Warszawa","SZUKAJ: fabryka Bielany Warszawa")
B9: Mokotow | C9: =HYPERLINK("https://www.google.com/maps/search/zarzadca+nieruchomosci+Mokotow+Warszawa","SZUKAJ: zarzadca nieruchomosci Mokotow Warszawa") | D9: =HYPERLINK("https://www.google.com/maps/search/firma+remontowa+Mokotow+Warszawa","SZUKAJ: firma remontowa Mokotow Warszawa") | E9: =HYPERLINK("https://www.google.com/maps/search/biuro+nieruchomosci+Mokotow+Warszawa","SZUKAJ: biuro nieruchomosci Mokotow Warszawa") | F9: =HYPERLINK("https://www.google.com/maps/search/fabryka+Mokotow+Warszawa","SZUKAJ: fabryka Mokotow Warszawa")
B10: Ochota | C10: =HYPERLINK("https://www.google.com/maps/search/zarzadca+nieruchomosci+Ochota+Warszawa","SZUKAJ: zarzadca nieruchomosci Ochota Warszawa") | D10: =HYPERLINK("https://www.google.com/maps/search/firma+remontowa+Ochota+Warszawa","SZUKAJ: firma remontowa Ochota Warszawa") | E10: =HYPERLINK("https://www.google.com/maps/search/biuro+nieruchomosci+Ochota+Warszawa","SZUKAJ: biuro nieruchomosci Ochota Warszawa") | F10: =HYPERLINK("https://www.google.com/maps/search/fabryka+Ochota+Warszawa","SZUKAJ: fabryka Ochota Warszawa")
B11: Praga-Poludnie | C11: =HYPERLINK("https://www.google.com/maps/search/zarzadca+nieruchomosci+Praga-Poludnie+Warszawa","SZUKAJ: zarzadca nieruchomosci Praga-Poludnie Warszawa") | D11: =HYPERLINK("https://www.google.com/maps/search/firma+remontowa+Praga-Poludnie+Warszawa","SZUKAJ: firma remontowa Praga-Poludnie Warszawa") | E11: =HYPERLINK("https://www.google.com/maps/search/biuro+nieruchomosci+Praga-Poludnie+Warszawa","SZUKAJ: biuro nieruchomosci Praga-Poludnie Warszawa") | F11: =HYPERLINK("https://www.google.com/maps/search/fabryka+Praga-Poludnie+Warszawa","SZUKAJ: fabryka Praga-Poludnie Warszawa")
B12: Praga-Polnoc | C12: =HYPERLINK("https://www.google.com/maps/search/zarzadca+nieruchomosci+Praga-Polnoc+Warszawa","SZUKAJ: zarzadca nieruchomosci Praga-Polnoc Warszawa") | D12: =HYPERLINK("https://www.google.com/maps/search/firma+remontowa+Praga-Polnoc+Warszawa","SZUKAJ: firma remontowa Praga-Polnoc Warszawa") | E12: =HYPERLINK("https://www.google.com/maps/search/biuro+nieruchomosci+Praga-Polnoc+Warszawa","SZUKAJ: biuro nieruchomosci Praga-Polnoc Warszawa") | F12: =HYPERLINK("https://www.google.com/maps/search/fabryka+Praga-Polnoc+Warszawa","SZUKAJ: fabryka Praga-Polnoc Warszawa")
B13: Rembertow | C13: =HYPERLINK("https://www.google.com/maps/search/zarzadca+nieruchomosci+Rembertow+Warszawa","SZUKAJ: zarzadca nieruchomosci Rembertow Warszawa") | D13: =HYPERLINK("https://www.google.com/maps/search/firma+remontowa+Rembertow+Warszawa","SZUKAJ: firma remontowa Rembertow Warszawa") | E13: =HYPERLINK("https://www.google.com/maps/search/biuro+nieruchomosci+Rembertow+Warszawa","SZUKAJ: biuro nieruchomosci Rembertow Warszawa") | F13: =HYPERLINK("https://www.google.com/maps/search/fabryka+Rembertow+Warszawa","SZUKAJ: fabryka Rembertow Warszawa")
B14: Srodmiescie | C14: =HYPERLINK("https://www.google.com/maps/search/zarzadca+nieruchomosci+Srodmiescie+Warszawa","SZUKAJ: zarzadca nieruchomosci Srodmiescie Warszawa") | D14: =HYPERLINK("https://www.google.com/maps/search/firma+remontowa+Srodmiescie+Warszawa","SZUKAJ: firma remontowa Srodmiescie Warszawa") | E14: =HYPERLINK("https://www.google.com/maps/search/biuro+nieruchomosci+Srodmiescie+Warszawa","SZUKAJ: biuro nieruchomosci Srodmiescie Warszawa") | F14: =HYPERLINK("https://www.google.com/maps/search/fabryka+Srodmiescie+Warszawa","SZUKAJ: fabryka Srodmiescie Warszawa")
B15: Targowek | C15: =HYPERLINK("https://www.google.com/maps/search/zarzadca+nieruchomosci+Targowek+Warszawa","SZUKAJ: zarzadca nieruchomosci Targowek Warszawa") | D15: =HYPERLINK("https://www.google.com/maps/search/firma+remontowa+Targowek+Warszawa","SZUKAJ: firma remontowa Targowek Warszawa") | E15: =HYPERLINK("https://www.google.com/maps/search/biuro+nieruchomosci+Targowek+Warszawa","SZUKAJ: biuro nieruchomosci Targowek Warszawa") | F15: =HYPERLINK("https://www.google.com/maps/search/fabryka+Targowek+Warszawa","SZUKAJ: fabryka Targowek Warszawa")
B16: Ursus | C16: =HYPERLINK("https://www.google.com/maps/search/zarzadca+nieruchomosci+Ursus+Warszawa","SZUKAJ: zarzadca nieruchomosci Ursus Warszawa") | D16: =HYPERLINK("https://www.google.com/maps/search/firma+remontowa+Ursus+Warszawa","SZUKAJ: firma remontowa Ursus Warszawa") | E16: =HYPERLINK("https://www.google.com/maps/search/biuro+nieruchomosci+Ursus+Warszawa","SZUKAJ: biuro nieruchomosci Ursus Warszawa") | F16: =HYPERLINK("https://www.google.com/maps/search/fabryka+Ursus+Warszawa","SZUKAJ: fabryka Ursus Warszawa")
B17: Ursynow | C17: =HYPERLINK("https://www.google.com/maps/search/zarzadca+nieruchomosci+Ursynow+Warszawa","SZUKAJ: zarzadca nieruchomosci Ursynow Warszawa") | D17: =HYPERLINK("https://www.google.com/maps/search/firma+remontowa+Ursynow+Warszawa","SZUKAJ: firma remontowa Ursynow Warszawa") | E17: =HYPERLINK("https://www.google.com/maps/search/biuro+nieruchomosci+Ursynow+Warszawa","SZUKAJ: biuro nieruchomosci Ursynow Warszawa") | F17: =HYPERLINK("https://www.google.com/maps/search/fabryka+Ursynow+Warszawa","SZUKAJ: fabryka Ursynow Warszawa")
B18: Wawer | C18: =HYPERLINK("https://www.google.com/maps/search/zarzadca+nieruchomosci+Wawer+Warszawa","SZUKAJ: zarzadca nieruchomosci Wawer Warszawa") | D18: =HYPERLINK("https://www.google.com/maps/search/firma+remontowa+Wawer+Warszawa","SZUKAJ: firma remontowa Wawer Warszawa") | E18: =HYPERLINK("https://www.google.com/maps/search/biuro+nieruchomosci+Wawer+Warszawa","SZUKAJ: biuro nieruchomosci Wawer Warszawa") | F18: =HYPERLINK("https://www.google.com/maps/search/fabryka+Wawer+Warszawa","SZUKAJ: fabryka Wawer Warszawa")
B19: Wesola | C19: =HYPERLINK("https://www.google.com/maps/search/zarzadca+nieruchomosci+Wesola+Warszawa","SZUKAJ: zarzadca nieruchomosci Wesola Warszawa") | D19: =HYPERLINK("https://www.google.com/maps/search/firma+remontowa+Wesola+Warszawa","SZUKAJ: firma remontowa Wesola Warszawa") | E19: =HYPERLINK("https://www.google.com/maps/search/biuro+nieruchomosci+Wesola+Warszawa","SZUKAJ: biuro nieruchomosci Wesola Warszawa") | F19: =HYPERLINK("https://www.google.com/maps/search/fabryka+Wesola+Warszawa","SZUKAJ: fabryka Wesola Warszawa")
B20: Wilanow | C20: =HYPERLINK("https://www.google.com/maps/search/zarzadca+nieruchomosci+Wilanow+Warszawa","SZUKAJ: zarzadca nieruchomosci Wilanow Warszawa") | D20: =HYPERLINK("https://www.google.com/maps/search/firma+remontowa+Wilanow+Warszawa","SZUKAJ: firma remontowa Wilanow Warszawa") | E20: =HYPERLINK("https://www.google.com/maps/search/biuro+nieruchomosci+Wilanow+Warszawa","SZUKAJ: biuro nieruchomosci Wilanow Warszawa") | F20: =HYPERLINK("https://www.google.com/maps/search/fabryka+Wilanow+Warszawa","SZUKAJ: fabryka Wilanow Warszawa")
B21: Wlochy | C21: =HYPERLINK("https://www.google.com/maps/search/zarzadca+nieruchomosci+Wlochy+Warszawa","SZUKAJ: zarzadca nieruchomosci Wlochy Warszawa") | D21: =HYPERLINK("https://www.google.com/maps/search/firma+remontowa+Wlochy+Warszawa","SZUKAJ: firma remontowa Wlochy Warszawa") | E21: =HYPERLINK("https://www.google.com/maps/search/biuro+nieruchomosci+Wlochy+Warszawa","SZUKAJ: biuro nieruchomosci Wlochy Warszawa") | F21: =HYPERLINK("https://www.google.com/maps/search/fabryka+Wlochy+Warszawa","SZUKAJ: fabryka Wlochy Warszawa")
B22: Wola | C22: =HYPERLINK("https://www.google.com/maps/search/zarzadca+nieruchomosci+Wola+Warszawa","SZUKAJ: zarzadca nieruchomosci Wola Warszawa") | D22: =HYPERLINK("https://www.google.com/maps/search/firma+remontowa+Wola+Warszawa","SZUKAJ: firma remontowa Wola Warszawa") | E22: =HYPERLINK("https://www.google.com/maps/search/biuro+nieruchomosci+Wola+Warszawa","SZUKAJ: biuro nieruchomosci Wola Warszawa") | F22: =HYPERLINK("https://www.google.com/maps/search/fabryka+Wola+Warszawa","SZUKAJ: fabryka Wola Warszawa")
B23: Zoliborz | C23: =HYPERLINK("https://www.google.com/maps/search/zarzadca+nieruchomosci+Zoliborz+Warszawa","SZUKAJ: zarzadca nieruchomosci Zoliborz Warszawa") | D23: =HYPERLINK("https://www.google.com/maps/search/firma+remontowa+Zoliborz+Warszawa","SZUKAJ: firma remontowa Zoliborz Warszawa") | E23: =HYPERLINK("https://www.google.com/maps/search/biuro+nieruchomosci+Zoliborz+Warszawa","SZUKAJ: biuro nieruchomosci Zoliborz Warszawa") | F23: =HYPERLINK("https://www.google.com/maps/search/fabryka+Zoliborz+Warszawa","SZUKAJ: fabryka Zoliborz Warszawa")
B26: Alternatywne zapytania (klikalne) - gdy pierwsza tura da malo wynikow
B27: Segment | C27: Dzielnica | D27: Alternatywa 2 / 3
B28: Zarzadcy nieruchomosci | C28: Bemowo | D28: =HYPERLINK("https://www.google.com/maps/search/spoldzielnia+mieszkaniowa+Bemowo+Warszawa","SZUKAJ: spoldzielnia mieszkaniowa Bemowo Warszawa")
B29: Zarzadcy nieruchomosci | C29: Bemowo | D29: =HYPERLINK("https://www.google.com/maps/search/wspolnota+mieszkaniowa+Bemowo+Warszawa","SZUKAJ: wspolnota mieszkaniowa Bemowo Warszawa")
B30: Firmy budowlane | C30: Bemowo | D30: =HYPERLINK("https://www.google.com/maps/search/deweloper+Bemowo+Warszawa","SZUKAJ: deweloper Bemowo Warszawa")
B31: Firmy budowlane | C31: Bemowo | D31: =HYPERLINK("https://www.google.com/maps/search/generalny+wykonawca+Bemowo+Warszawa","SZUKAJ: generalny wykonawca Bemowo Warszawa")
B32: Agencje nieruchomosci | C32: Bemowo | D32: =HYPERLINK("https://www.google.com/maps/search/agencja+nieruchomosci+Bemowo+Warszawa","SZUKAJ: agencja nieruchomosci Bemowo Warszawa")
B33: HR / Duzi pracodawcy | C33: Bemowo | D33: =HYPERLINK("https://www.google.com/maps/search/centrum+logistyczne+Bemowo+Warszawa","SZUKAJ: centrum logistyczne Bemowo Warszawa")
B34: HR / Duzi pracodawcy | C34: Bemowo | D34: =HYPERLINK("https://www.google.com/maps/search/hotel+Bemowo+Warszawa","SZUKAJ: hotel Bemowo Warszawa")
B35: Zarzadcy nieruchomosci | C35: Bialoleka | D35: =HYPERLINK("https://www.google.com/maps/search/spoldzielnia+mieszkaniowa+Bialoleka+Warszawa","SZUKAJ: spoldzielnia mieszkaniowa Bialoleka Warszawa")
B36: Zarzadcy nieruchomosci | C36: Bialoleka | D36: =HYPERLINK("https://www.google.com/maps/search/wspolnota+mieszkaniowa+Bialoleka+Warszawa","SZUKAJ: wspolnota mieszkaniowa Bialoleka Warszawa")
B37: Firmy budowlane | C37: Bialoleka | D37: =HYPERLINK("https://www.google.com/maps/search/deweloper+Bialoleka+Warszawa","SZUKAJ: deweloper Bialoleka Warszawa")
B38: Firmy budowlane | C38: Bialoleka | D38: =HYPERLINK("https://www.google.com/maps/search/generalny+wykonawca+Bialoleka+Warszawa","SZUKAJ: generalny wykonawca Bialoleka Warszawa")
B39: Agencje nieruchomosci | C39: Bialoleka | D39: =HYPERLINK("https://www.google.com/maps/search/agencja+nieruchomosci+Bialoleka+Warszawa","SZUKAJ: agencja nieruchomosci Bialoleka Warszawa")
B40: HR / Duzi pracodawcy | C40: Bialoleka | D40: =HYPERLINK("https://www.google.com/maps/search/centrum+logistyczne+Bialoleka+Warszawa","SZUKAJ: centrum logistyczne Bialoleka Warszawa")
B41: HR / Duzi pracodawcy | C41: Bialoleka | D41: =HYPERLINK("https://www.google.com/maps/search/hotel+Bialoleka+Warszawa","SZUKAJ: hotel Bialoleka Warszawa")
B42: Zarzadcy nieruchomosci | C42: Bielany | D42: =HYPERLINK("https://www.google.com/maps/search/spoldzielnia+mieszkaniowa+Bielany+Warszawa","SZUKAJ: spoldzielnia mieszkaniowa Bielany Warszawa")
B43: Zarzadcy nieruchomosci | C43: Bielany | D43: =HYPERLINK("https://www.google.com/maps/search/wspolnota+mieszkaniowa+Bielany+Warszawa","SZUKAJ: wspolnota mieszkaniowa Bielany Warszawa")
B44: Firmy budowlane | C44: Bielany | D44: =HYPERLINK("https://www.google.com/maps/search/deweloper+Bielany+Warszawa","SZUKAJ: deweloper Bielany Warszawa")
...

Sheet Plan tygodnia
B2: Rhythm dnia - typowy dzien 8h (Pon-Pt)
B4: Godzina | C4: Co robisz | D4: Cel
B5: 9:00 - 9:15 | C5: Kawa, przeglad CRM-a | D5: Filtruj [Lista firm] po kolumnie [Data follow-up] - najstarsze na gore
B6: 9:15 - 10:30 | C6: Blok 1: 8-10 rozmow | D6: Rano = Zarzadcy nieruchomosci (najlepiej odbieraja)
B7: 10:30 - 10:45 | C7: Przerwa - spacer, woda | D7: Zapisz notatki z ostatnich 3 rozmow ZANIM zapomnisz
B8: 10:45 - 12:00 | C8: Blok 2: 8-10 rozmow | D8: Firmy budowlane (kierownik budowy w biurze)
B9: 12:00 - 13:00 | C9: Lunch | D9: Nie dzwon w czasie lunchu - inni tez jedza
B10: 13:00 - 14:30 | C10: Blok 3: 6-8 rozmow | D10: Agencje nieruchomosci LUB HR (wtorek / sroda / czwartek)
B11: 14:30 - 15:00 | C11: Follow-up | D11: Wyslij SMS-y z szablonow (patrz reklama/29-lista-firm-do-dzwonienia.md)
B12: 15:00 - 16:00 | C12: Research nowych firm | D12: Arkusz [Google Maps Warszawa] - dodaj 10-20 firm na jutro
B15: Target tygodniowy (realny)
B16: 100-120 | C16: Rozmow w tygodniu (20-25 / dzien) | D16: Nie wiecej - zmeczenie glosu = zly vibe rozmowy
B17: 30-36 | C17: Rozmow z decydentem (konwersja 30%) | D17: Reszta: sekretariat, brak odbioru, nieprawidlowy numer
B18: 15-18 | C18: Osob slucha do konca (50% z decydentow) | D18: To sa twoje realne szanse sprzedazowe
B19: 5-6 | C19: Nowych firm rejestruje sie (30% z sluchaczy) | D19: Tydzien sukcesu - 20+ / miesiac z telefonow

Sheet Pre-flight
B2: Pre-flight checklist - zanim zadzwonisz pierwszy raz
B3: Nie dzwonisz dopoki wszystko ponizej nie jest zafajkowane. Spali sie pierwsza rozmowa.
B5: [ ] | C5: Mam liste 50+ firm w arkuszu [Lista firm] (segment 1 lub 1+2)
B6: [ ] | C6: Kazda ZIELONA firma ma telefon, adres, 1-zdaniowa notatke z researchu (kolumna S)
B7: [ ] | C7: Kazda ZIELONA firma ma - jesli znalazlem - imie osoby kontaktowej (kolumna K)
B8: [ ] | C8: Mam wydrukowany scenariusz rozmowy (reklama/27-scenariusz-rozmowy-telefonicznej.md)
B9: [ ] | C9: Mam wydrukowana liste obiekcji (reklama/28-obsluga-obiekcji-telefon.md) OBOK telefonu
B10: [ ] | C10: Mam gotowe 5 szablonow SMS po rozmowie (reklama/29-lista-firm-do-dzwonienia.md)
B11: [ ] | C11: Mam gotowy szablon maila po rozmowie (reklama/20-email-onboarding.md)
B12: [ ] | C12: Wylaczone powiadomienia - telefon, laptop, Slack, cokolwiek co moze brzeknac
B13: [ ] | C13: Stoje lub siedze wyprostowany (sylwetka = glos = wiarygodnosc)
B14: [ ] | C14: Obok mam wode i notatnik (papierowy - szybciej niz wpisywanie do Excela w trakcie)
B15: [ ] | C15: Zrobilem 5 min rozgrzewki glosu (zaspiewac abc, otworzyc szczeke, spacer)
B16: [ ] | C16: Wiem ze pierwszy telefon bedzie NAJTRUDNIEJSZY - po 5. juz idzie plynnie
B19: ! | C19: Zasada: dzien 1 = 10 telefonow z ZIELONYCH. Nie cala lista. Nie 50 naraz. 10. Zmierz czas. Zapisz notatki. Jutro 15. Piatego dnia masz juz flow.

Sheet Metryki
B2: Metryki - auto-liczone z arkusza [Lista firm]
B3: Formuly zliczaja sie same. Wypelnij Lista firm, wroc tutaj, zobacz progres.
B5: Lejek sprzedazy - aktualny stan
B6: Firmy w bazie (lacznie) | C6: =COUNTA('Lista firm'!C2:C301) | D6: Ile firm w ogole masz w CRM
B7: Z czego TOP (zielony) | C7: =COUNTIF('Lista firm'!E2:E301,"TOP (zielony)") | D7: Do tych dzwonisz jako pierwsze
B8: Z czego Sredni (zolty) | C8: =COUNTIF('Lista firm'!E2:E301,"Sredni (zolty)") | D8: Druga kolejka
B9: Z czego Niski (czerwony) | C9: =COUNTIF('Lista firm'!E2:E301,"Niski (czerwony)") | D9: Pomijasz na start
B11: Zadzwoniono (lacznie) | C11: =COUNTIF('Lista firm'!P2:P301,"Zadzwoniono - brak odbioru")+COUNTIF('Lista firm'!P2:P301,"Zadzwoniono - rozmowa")+COUNTIF('Lista firm'!P2:P301,"W kontakcie")+COUNTIF('Lista firm'!P2:P301,"Zarejestrowana")+COUNTIF('Lista firm'!P2:P301,"Odrzucona")+COUNTIF('Lista firm'!P2:P301,"Callback") | D11: Liczba firm gdzie podjales probe
B12: Rozmowa z decydentem | C12: =COUNTIF('Lista firm'!P2:P301,"Zadzwoniono - rozmowa")+COUNTIF('Lista firm'!P2:P301,"W kontakcie")+COUNTIF('Lista firm'!P2:P301,"Zarejestrowana")+COUNTIF('Lista firm'!P2:P301,"Odrzucona")+COUNTIF('Lista firm'!P2:P301,"Callback") | D12: Gdzie rozmowa faktycznie sie odbyla
B13: Zarejestrowane firmy | C13: =COUNTIF('Lista firm'!P2:P301,"Zarejestrowana") | D13: TWOJE WYGRANE - ten numer rosnie
B14: Odrzucone | C14: =COUNTIF('Lista firm'!P2:P301,"Odrzucona") | D14: Uczysz sie na bledach - zobacz notatki z rozmowy
B15: W kontakcie / callback | C15: =COUNTIF('Lista firm'!P2:P301,"W kontakcie")+COUNTIF('Lista firm'!P2:P301,"Callback") | D15: Pilnuj daty follow-up - sam cie podswietli na czerwono
B18: Konwersje (auto)
B19: % dodzwanialnosci (decydent / zadzwoniono) | C19: =IFERROR((COUNTIF('Lista firm'!P2:P301,"Zadzwoniono - rozmowa")+COUNTIF('Lista firm'!P2:P301,"W kontakcie")+COUNTIF('Lista firm'!P2:P301,"Zarejestrowana")+COUNTIF('Lista firm'!P2:P301,"Odrzucona")+COUNTIF('Lista firm'!P2:P301,"Callback"))/(COUNTIF('Lista firm'!P2:P301,"Zadzwoniono - brak odbioru")+COUNTIF('Lista firm'!P2:P301,"Zadzwoniono - rozmowa")+COUNTIF('Lista firm'!P2:P301,"W kontakcie")+COUNTIF('Lista firm'!P2:P301,"Zarejestrowana")+COUNTIF('Lista firm'!P2:P301,"Odrzucona")+COUNTIF('Lista firm'!P2:P301,"Callback")),0) | D19: Cel: 30%. Jesli <20% - dzwonisz nie w tych godzinach, sprawdz [Plan tygodnia].
B20: % rejestracji (zarejestrowana / decydent) | C20: =IFERROR(COUNTIF('Lista firm'!P2:P301,"Zarejestrowana")/(COUNTIF('Lista firm'!P2:P301,"Zadzwoniono - rozmowa")+COUNTIF('Lista firm'!P2:P301,"W kontakcie")+COUNTIF('Lista firm'!P2:P301,"Zarejestrowana")+COUNTIF('Lista firm'!P2:P301,"Odrzucona")+COUNTIF('Lista firm'!P2:P301,"Callback")),0) | D20: Cel: 15-30%. Jesli <10% - skrypt nie dziala, zobacz reklama/28-obsluga-obiekcji.
B21: % end-to-end (zarejestrowana / firmy w bazie) | C21: =IFERROR(COUNTIF('Lista firm'!P2:P301,"Zarejestrowana")/COUNTA('Lista firm'!C2:C301),0) | D21: Cel: 5%. Mierz na poziomie miesiacznym - pojedynczy dzien ma za malo danych.
